<?xml version="1.0"?>
<sdf version="1.7">
  <model name="iiwa7_2">
    <link name="iiwa_link_7">
      <inertial>
        <pose>-0.013 0 0.07 0 0 0</pose>
        <mass>3.863</mass>
        <inertia>
          <ixx>0.0141</ixx>
          <ixy>0</ixy>
          <ixz>0</ixz>
          <iyy>0.0171</iyy>
          <iyz>0</iyz>
          <izz>0.0178</izz>
        </inertia>
      </inertial>
      <visual name="iiwa_link_7_visual">
        <geometry>
          <mesh>
            <scale>1 1 1</scale>
            <uri>link_7.obj</uri>
          </mesh>
        </geometry>
        <material>
          <diffuse>0.4 0.4 0.4 1.0</diffuse>
        </material>
      </visual>
      <collision name="iiwa_link_7_collision">
        <pose>-0.004563 0 0.07875 0 0 0</pose>
        <geometry>
          <box>
            <size>0.216874 0.207874 0.1575</size>
          </box>
        </geometry>
      </collision>
      <gravity>1</gravity>
      <velocity_decay/>
      <self_collide>0</self_collide>
    </link>
    <link name="iiwa_link_8">
      <pose>0 0 0.1575 0 0 0</pose>
      <inertial>
        <pose>0 -0.0347 0.113 0 0 0</pose>
        <mass>2.7025</mass>
        <inertia>
          <ixx>0.0171</ixx>
          <ixy>0</ixy>
          <ixz>0</ixz>
          <iyy>0.0163</iyy>
          <iyz>0</iyz>
          <izz>0.006</izz>
        </inertia>
      </inertial>
      <visual name="iiwa_link_8_visual">
        <geometry>
          <mesh>
            <scale>1 1 1</scale>
            <uri>link_8.obj</uri>
          </mesh>
        </geometry>
        <material>
          <diffuse>0.4 0.4 0.4 1.0</diffuse>
        </material>
      </visual>
      <collision name="iiwa_link_8_collision">
        <pose>0 -0.023301 0.127997 0 0 0</pose>
        <geometry>
          <box>
            <size>0.13596 0.182584 0.260995</size>
          </box>
        </geometry>
      </collision>
      <gravity>1</gravity>
      <velocity_decay/>
      <self_collide>0</self_collide>
    </link>
    <joint name="iiwa_joint_8" type="revolute">
      <child>iiwa_link_8</child>
      <parent>iiwa_link_7</parent>
      <axis>
        <xyz expressed_in="__model__">0 0 1</xyz>
        <limit>
          <lower>-2.96706</lower>
          <upper>2.96706</upper>
          <effort>300</effort>
          <velocity>10</velocity>
        </limit>
        <dynamics>
          <damping>0.0</damping>
          <friction>0</friction>
          <spring_reference>0</spring_reference>
          <spring_stiffness>0</spring_stiffness>
        </dynamics>
      </axis>
    </joint>
    <link name="iiwa_link_9">
      <pose>0 0 0.3405 1.5708 0 -3.14159</pose>
      <inertial>
        <pose>0.000 0.0668 0.0344 0 0 0</pose>
        <mass>2.7258</mass>
        <inertia>
          <ixx>0.0170</ixx>
          <ixy>0</ixy>
          <ixz>0</ixz>
          <iyy>0.0162</iyy>
          <iyz>0</iyz>
          <izz>0.0061</izz>
        </inertia>
      </inertial>
      <visual name="iiwa_link_9_visual">
        <geometry>
          <mesh>
            <scale>1 1 1</scale>
            <uri>link_9.obj</uri>
          </mesh>
        </geometry>
        <material>
          <diffuse>1.0 0.423529411765 0.0392156862745 1.0</diffuse>
        </material>
      </visual>
      <collision name="iiwa_link_9_collision">
        <pose>0 0.0580045 0.0173035 0 0 0</pose>
        <geometry>
          <box>
            <size>0.135988 0.251991 0.182605</size>
          </box>
        </geometry>
      </collision>
      <gravity>1</gravity>
      <velocity_decay/>
      <self_collide>0</self_collide>
    </link>
    <joint name="iiwa_joint_9" type="revolute">
      <child>iiwa_link_9</child>
      <parent>iiwa_link_8</parent>
      <axis>
        <xyz expressed_in="__model__">-0 1 0</xyz>
        <limit>
          <lower>-2.0944</lower>
          <upper>2.0944</upper>
          <effort>300</effort>
          <velocity>10</velocity>
        </limit>
        <dynamics>
          <damping>0</damping>
          <friction>0</friction>
          <spring_reference>0</spring_reference>
          <spring_stiffness>0</spring_stiffness>
        </dynamics>
      </axis>
    </joint>
    <link name="iiwa_link_10">
      <pose>0 0 0.5245 0 0 0</pose>
      <inertial>
        <pose>0 0.0296 0.1265 0 0 0</pose>
        <mass>3.175</mass>
        <inertia>
          <ixx>0.025</ixx>
          <ixy>0</ixy>
          <ixz>0</ixz>
          <iyy>0.0238</iyy>
          <iyz>0</iyz>
          <izz>0.0076</izz>
        </inertia>
      </inertial>
      <visual name="iiwa_link_10_visual">
        <geometry>
          <mesh>
            <scale>1 1 1</scale>
            <uri>link_10.obj</uri>
          </mesh>
        </geometry>
        <material>
          <diffuse>0.4 0.4 0.4 1.0</diffuse>
        </material>
      </visual>
      <collision name="iiwa_link_10_collision">
        <pose>0 0.0182965 0.11073 0 0 0</pose>
        <geometry>
          <box>
            <size>0.135987 0.182593 0.29346</size>
          </box>
        </geometry>
      </collision>
      <gravity>1</gravity>
      <velocity_decay/>
      <self_collide>0</self_collide>
    </link>
    <joint name="iiwa_joint_10" type="revolute">
      <child>iiwa_link_10</child>
      <parent>iiwa_link_9</parent>
      <axis>
        <xyz expressed_in="__model__">0 0 1</xyz>
        <limit>
          <lower>-2.96706</lower>
          <upper>2.96706</upper>
          <effort>300</effort>
          <velocity>10</velocity>
        </limit>
        <dynamics>
          <damping>0</damping>
          <friction>0</friction>
          <spring_reference>0</spring_reference>
          <spring_stiffness>0</spring_stiffness>
        </dynamics>
      </axis>
    </joint>
    <link name="iiwa_link_11">
      <pose>0 0 0.74 1.5708 0 0</pose>
      <inertial>
        <pose>0 0.067 0.034 0 0 0</pose>
        <mass>2.73</mass>
        <inertia>
          <ixx>0.017</ixx>
          <ixy>0</ixy>
          <ixz>0</ixz>
          <iyy>0.0162</iyy>
          <iyz>0</iyz>
          <izz>0.0061</izz>
        </inertia>
      </inertial>
      <visual name="iiwa_link_11_visual">
        <geometry>
          <mesh>
            <scale>1 1 1</scale>
            <uri>link_11.obj</uri>
          </mesh>
        </geometry>
        <material>
          <diffuse>1.0 0.423529411765 0.0392156862745 1.0</diffuse>
        </material>
      </visual>
      <collision name="iiwa_link_11_collision">
        <pose>0 0.0580045 0.0233035 0 0 0</pose>
        <geometry>
          <box>
            <size>0.135988 0.251991 0.182605</size>
          </box>
        </geometry>
      </collision>
      <gravity>1</gravity>
      <velocity_decay/>
      <self_collide>0</self_collide>
    </link>
    <joint name="iiwa_joint_11" type="revolute">
      <child>iiwa_link_11</child>
      <parent>iiwa_link_10</parent>
      <axis>
        <xyz expressed_in="__model__">0 -1 0</xyz>
        <limit>
          <lower>-2.0944</lower>
          <upper>2.0944</upper>
          <effort>300</effort>
          <velocity>10</velocity>
        </limit>
        <dynamics>
          <damping>0</damping>
          <friction>0</friction>
          <spring_reference>0</spring_reference>
          <spring_stiffness>0</spring_stiffness>
        </dynamics>
      </axis>
    </joint>
    <link name="iiwa_link_12">
      <pose>0 0 0.924 0 0 -3.14159</pose>
      <inertial>
        <pose>0.0001 0.021 0.076 0 0 0</pose>
        <mass>1.69</mass>
        <inertia>
          <ixx>0.01</ixx>
          <ixy>0</ixy>
          <ixz>0</ixz>
          <iyy>0.0087</iyy>
          <iyz>0</iyz>
          <izz>0.00449</izz>
        </inertia>
      </inertial>
      <visual name="iiwa_link_12_visual">
        <geometry>
          <mesh>
            <scale>1 1 1</scale>
            <uri>link_12.obj</uri>
          </mesh>
        </geometry>
        <material>
          <diffuse>0.4 0.4 0.4 1.0</diffuse>
        </material>
      </visual>
      <collision name="iiwa_link_12_collision">
        <pose>0 0.015546 0.102458 0 0 0</pose>
        <geometry>
          <box>
            <size>0.135999 0.167092 0.276916</size>
          </box>
        </geometry>
      </collision>
      <gravity>1</gravity>
      <velocity_decay/>
      <self_collide>0</self_collide>
    </link>
    <joint name="iiwa_joint_12" type="revolute">
      <child>iiwa_link_12</child>
      <parent>iiwa_link_11</parent>
      <axis>
        <xyz expressed_in="__model__">0 0 1</xyz>
        <limit>
          <lower>-2.96706</lower>
          <upper>2.96706</upper>
          <effort>300</effort>
          <velocity>10</velocity>
        </limit>
        <dynamics>
          <damping>0</damping>
          <friction>0</friction>
          <spring_reference>0</spring_reference>
          <spring_stiffness>0</spring_stiffness>
        </dynamics>
      </axis>
    </joint>
    <link name="iiwa_link_13">
      <pose>0 0 1.1395 1.5708 0 -3.14159</pose>
      <inertial>
        <pose>0 0.0026 0.0005 0 0 0</pose>
        <mass>1.8</mass>
        <inertia>
          <ixx>0.0051</ixx>
          <ixy>0</ixy>
          <ixz>0</ixz>
          <iyy>0.0049</iyy>
          <iyz>0</iyz>
          <izz>0.0035</izz>
        </inertia>
      </inertial>
      <visual name="iiwa_link_13_visual">
        <pose>0 0 -0.060700 0 0 0</pose>
        <geometry>
          <mesh>
            <scale>1 1 1</scale>
            <uri>link_13.obj</uri>
          </mesh>
        </geometry>
        <material>
          <diffuse>1.0 0.423529411765 0.0392156862745 1.0</diffuse>
        </material>
      </visual>
      <collision name="iiwa_link_13_collision">
        <geometry>
          <box>
            <size>0.132334 0.177387 0.137409</size>
          </box>
        </geometry>
      </collision>
      <gravity>1</gravity>
      <velocity_decay/>
      <self_collide>0</self_collide>
    </link>
    <joint name="iiwa_joint_13" type="revolute">
      <child>iiwa_link_13</child>
      <parent>iiwa_link_12</parent>
      <axis>
        <xyz expressed_in="__model__">-0 1 -0</xyz>
        <limit>
          <lower>-2.0944</lower>
          <upper>2.0944</upper>
          <effort>300</effort>
          <velocity>10</velocity>
        </limit>
        <dynamics>
          <damping>0</damping>
          <friction>0</friction>
          <spring_reference>0</spring_reference>
          <spring_stiffness>0</spring_stiffness>
        </dynamics>
      </axis>
    </joint>
    <link name="iiwa_link_14">
      <pose>0 0 1.22 0 0 0</pose>
      <inertial>
        <pose>0 0 0.0294 0 0 0</pose>
        <mass>.4</mass>
        <inertia>
          <ixx>0.0004</ixx>
          <ixy>0</ixy>
          <ixz>0</ixz>
          <iyy>0.0004</iyy>
          <iyz>0</iyz>
          <izz>0.0005</izz>
        </inertia>
      </inertial>
      <visual name="iiwa_link_14_visual">
        <geometry>
          <mesh>
            <scale>1 1 1</scale>
            <uri>link_14.obj</uri>
          </mesh>
        </geometry>
        <material>
          <diffuse>0.4 0.4 0.4 1.0</diffuse>
        </material>
      </visual>
      <collision name="iiwa_link_14_collision">
        <pose>0 0 0.021997 0 0 0</pose>
        <geometry>
          <box>
            <size>0.10385 0.103885 0.045</size>
          </box>
        </geometry>
      </collision>
      <gravity>1</gravity>
      <velocity_decay/>
      <self_collide>0</self_collide>
    </link>
    <joint name="iiwa_joint_14" type="revolute">
      <child>iiwa_link_14</child>
      <parent>iiwa_link_13</parent>
      <axis>
        <xyz expressed_in="__model__">0 0 1</xyz>
        <limit>
          <lower>-3.05433</lower>
          <upper>3.05433</upper>
          <effort>300</effort>
          <velocity>10</velocity>
        </limit>
        <dynamics>
          <damping>0</damping>
          <friction>0</friction>
          <spring_reference>0</spring_reference>
          <spring_stiffness>0</spring_stiffness>
        </dynamics>
      </axis>
    </joint>
    <static>0</static>
    <plugin name="gazebo_ros_controller" filename="libgazebo_ros_control.so">
      <robotNamespace>/iiwa</robotNamespace>
    </plugin>
  </model>
</sdf>
